<?xml version="1.0" ?>
<!-- =================================================================================== -->
<!-- |    This document was autogenerated by xacro from braccio.xacro                  | -->
<!-- |    EDITING THIS FILE BY HAND IS NOT RECOMMENDED                                 | -->
<!-- =================================================================================== -->
<robot name="braccio">
    <material name="silver_default">
        <color rgba="0.700 0.700 0.700 1.000" />
    </material>
    <material name="generico">
        <color rgba="0.3137254901960784 0.3137254901960784 0.3137254901960784 1.0" />
    </material>
    <material name="opaque255255255">
        <color rgba="0.3137254901960784 0.3137254901960784 0.3137254901960784 1.0" />
    </material>
    <material name="krmozott_tengely">
        <color rgba="0.3137254901960784 0.3137254901960784 0.3137254901960784 1.0" />
    </material>
    <material name="liscia_rosso">
        <color rgba="0.3137254901960784 0.3137254901960784 0.3137254901960784 1.0" />
    </material>
    <material name="default">
        <color rgba="0.3137254901960784 0.3137254901960784 0.3137254901960784 1.0" />
    </material>
    <material name="liscia_giallo">
        <color rgba="0.3137254901960784 0.3137254901960784 0.3137254901960784 1.0" />
    </material>
    <material name="liscia_arancione_chiaro">
        <color rgba="0.3137254901960784 0.3137254901960784 0.3137254901960784 1.0" />
    </material>
    <transmission name="Azimuth_joint_tran">
        <type>transmission_interface/SimpleTransmission</type>
        <joint name="Azimuth_joint">
            <hardwareInterface>hardware_interface/EffortJointInterface</hardwareInterface>
        </joint>
        <actuator name="Azimuth_joint_actr">
            <hardwareInterface>hardware_interface/EffortJointInterface</hardwareInterface>
            <mechanicalReduction>1</mechanicalReduction>
        </actuator>
    </transmission>
    <transmission name="Elevation_joint_tran">
        <type>transmission_interface/SimpleTransmission</type>
        <joint name="Elevation_joint">
            <hardwareInterface>hardware_interface/EffortJointInterface</hardwareInterface>
        </joint>
        <actuator name="Elevation_joint_actr">
            <hardwareInterface>hardware_interface/EffortJointInterface</hardwareInterface>
            <mechanicalReduction>1</mechanicalReduction>
        </actuator>
    </transmission>
    <transmission name="Elbow_joint_tran">
        <type>transmission_interface/SimpleTransmission</type>
        <joint name="Elbow_joint">
            <hardwareInterface>hardware_interface/EffortJointInterface</hardwareInterface>
        </joint>
        <actuator name="Elbow_joint_actr">
            <hardwareInterface>hardware_interface/EffortJointInterface</hardwareInterface>
            <mechanicalReduction>1</mechanicalReduction>
        </actuator>
    </transmission>
    <transmission name="joint_3_tran">
        <type>transmission_interface/SimpleTransmission</type>
        <joint name="joint_3">
            <hardwareInterface>hardware_interface/EffortJointInterface</hardwareInterface>
        </joint>
        <actuator name="joint_3_actr">
            <hardwareInterface>hardware_interface/EffortJointInterface</hardwareInterface>
            <mechanicalReduction>1</mechanicalReduction>
        </actuator>
    </transmission>
    <transmission name="wrist_pitch_joint_tran">
        <type>transmission_interface/SimpleTransmission</type>
        <joint name="wrist_pitch_joint">
            <hardwareInterface>hardware_interface/EffortJointInterface</hardwareInterface>
        </joint>
        <actuator name="wrist_pitch_joint_actr">
            <hardwareInterface>hardware_interface/EffortJointInterface</hardwareInterface>
            <mechanicalReduction>1</mechanicalReduction>
        </actuator>
    </transmission>
    <transmission name="wrist_roll_joint_tran">
        <type>transmission_interface/SimpleTransmission</type>
        <joint name="wrist_roll_joint">
            <hardwareInterface>hardware_interface/EffortJointInterface</hardwareInterface>
        </joint>
        <actuator name="wrist_roll_joint_actr">
            <hardwareInterface>hardware_interface/EffortJointInterface</hardwareInterface>
            <mechanicalReduction>1</mechanicalReduction>
        </actuator>
    </transmission>
    <gazebo>
        <plugin filename="libgazebo_ros_control.so" name="control">
            <robotNamespace>braccio</robotNamespace>
        </plugin>
        <plugin filename="libgazebo_ros_control.so" name="gazebo_ros_control">
            <robotNamespace>/</robotNamespace>
        </plugin>
    </gazebo>
    <gazebo reference="base_link">
        <material>Gazebo/Silver</material>
        <mu1>0.2</mu1>
        <mu2>0.2</mu2>
        <selfCollide>true</selfCollide>
        <gravity>true</gravity>
    </gazebo>
    <gazebo reference="Base_braccio_1">
        <material>Gazebo/Silver</material>
        <mu1>0.2</mu1>
        <mu2>0.2</mu2>
        <selfCollide>true</selfCollide>
    </gazebo>
    <gazebo reference="link1_1">
        <material>Gazebo/Silver</material>
        <mu1>0.2</mu1>
        <mu2>0.2</mu2>
        <selfCollide>true</selfCollide>
    </gazebo>
    <gazebo reference="Elbow_1">
        <material>Gazebo/Silver</material>
        <mu1>0.2</mu1>
        <mu2>0.2</mu2>
        <selfCollide>true</selfCollide>
    </gazebo>
    <gazebo reference="Link2_1">
        <material>Gazebo/Silver</material>
        <mu1>0.2</mu1>
        <mu2>0.2</mu2>
        <selfCollide>true</selfCollide>
    </gazebo>
    <gazebo reference="wrist_1">
        <material>Gazebo/Silver</material>
        <mu1>0.2</mu1>
        <mu2>0.2</mu2>
        <selfCollide>true</selfCollide>
    </gazebo>
    <gazebo reference="palm_1">
        <material>Gazebo/Silver</material>
        <mu1>0.2</mu1>
        <mu2>0.2</mu2>
        <selfCollide>true</selfCollide>
    </gazebo>
    <link name="world" />
    <joint name="fixed" type="fixed">
        <parent link="world" />
        <child link="base_link" />
    </joint>
    <link name="base_link">
        <inertial>
            <origin rpy="0 0 0" xyz="0.0011783676870079772 1.0119793125755727e-05 0.20000571702403733" />
            <mass value="962.5851363558244" />
            <inertia ixx="25.726817" ixy="0.002039" ixz="0.061446" iyy="58.481615" iyz="0.00035" izz="58.394457" />
        </inertial>
        <visual>
            <origin rpy="0 0 0" xyz="0 0 0" />
            <geometry>
                <mesh filename="package://braccio_description/meshes/base_link.stl" scale="0.001 0.001 0.001" />
            </geometry>
            <material name="generico" />
        </visual>
        <collision>
            <origin rpy="0 0 0" xyz="0 0 0" />
            <geometry>
                <mesh filename="package://braccio_description/meshes/base_link.stl" scale="0.001 0.001 0.001" />
            </geometry>
        </collision>
    </link>
    <link name="Base_braccio_1">
        <inertial>
            <origin rpy="0 0 0" xyz="-0.08476368759412747 0.00011142407722511134 0.0324262511297288" />
            <mass value="1.5100627333156982" />
            <inertia ixx="0.000942" ixy="4e-06" ixz="-0.000374" iyy="0.004339" iyz="0.0" izz="0.004119" />
        </inertial>
        <visual>
            <origin rpy="0 0 0" xyz="-0.325006 0.0 -0.419949" />
            <geometry>
                <mesh filename="package://braccio_description/meshes/Base_braccio_1.stl" scale="0.001 0.001 0.001" />
            </geometry>
            <material name="opaque255255255" />
        </visual>
        <collision>
            <origin rpy="0 0 0" xyz="-0.325006 0.0 -0.419949" />
            <geometry>
                <mesh filename="package://braccio_description/meshes/Base_braccio_1.stl" scale="0.001 0.001 0.001" />
            </geometry>
        </collision>
    </link>
    <link name="link1_1">
        <inertial>
            <origin rpy="0 0 0" xyz="0.00032927538198956885 0.002383864798820145 0.14449735433995625" />
            <mass value="2.9321462543284906" />
            <inertia ixx="0.072624" ixy="2e-06" ixz="2.7e-05" iyy="0.068167" iyz="0.000225" izz="0.008492" />
        </inertial>
        <visual>
            <origin rpy="0 0 0" xyz="-0.325006 0.0 -0.477449" />
            <geometry>
                <mesh filename="package://braccio_description/meshes/link1_1.stl" scale="0.001 0.001 0.001" />
            </geometry>
            <material name="krmozott_tengely" />
        </visual>
        <collision>
            <origin rpy="0 0 0" xyz="-0.325006 0.0 -0.477449" />
            <geometry>
                <mesh filename="package://braccio_description/meshes/link1_1.stl" scale="0.001 0.001 0.001" />
            </geometry>
        </collision>
    </link>
    <link name="Elbow_1">
        <inertial>
            <origin rpy="0 0 0" xyz="-0.0367119124758008 -0.00016653450735915358 -0.007157327333499386" />
            <mass value="0.6426736774037254" />
            <inertia ixx="0.000753" ixy="6e-06" ixz="-0.000225" iyy="0.001437" iyz="2e-06" izz="0.001393" />
        </inertial>
        <visual>
            <origin rpy="0 0 0" xyz="-0.325006 0.0 -0.822449" />
            <geometry>
                <mesh filename="package://braccio_description/meshes/Elbow_1.stl" scale="0.001 0.001 0.001" />
            </geometry>
            <material name="liscia_rosso" />
        </visual>
        <collision>
            <origin rpy="0 0 0" xyz="-0.325006 0.0 -0.822449" />
            <geometry>
                <mesh filename="package://braccio_description/meshes/Elbow_1.stl" scale="0.001 0.001 0.001" />
            </geometry>
        </collision>
    </link>
    <link name="Link2_1">
        <inertial>
            <origin rpy="0 0 0" xyz="0.00013861422739491758 -0.00012821429677497114 0.02594338331463375" />
            <mass value="0.9299242223980831" />
            <inertia ixx="0.026509" ixy="0.0" ixz="0.000384" iyy="0.027097" iyz="3.5e-05" izz="0.00115" />
        </inertial>
        <visual>
            <origin rpy="0 0 0" xyz="-0.325006 0.0 -0.784449" />
            <geometry>
                <mesh filename="package://braccio_description/meshes/Link2_1.stl" scale="0.001 0.001 0.001" />
            </geometry>
            <material name="default" />
        </visual>
        <collision>
            <origin rpy="0 0 0" xyz="-0.325006 0.0 -0.784449" />
            <geometry>
                <mesh filename="package://braccio_description/meshes/Link2_1.stl" scale="0.001 0.001 0.001" />
            </geometry>
        </collision>
    </link>
    <link name="wrist_1">
        <inertial>
            <origin rpy="0 0 0" xyz="2.9160791963467325e-05 -0.0026833097699450817 0.00015988220563789568" />
            <mass value="0.07667109056502067" />
            <inertia ixx="6e-05" ixy="-0.0" ixz="-0.0" iyy="3.3e-05" iyz="4e-06" izz="6.5e-05" />
        </inertial>
        <visual>
            <origin rpy="0 0 0" xyz="-0.325306 0.0002 -1.166901" />
            <geometry>
                <mesh filename="package://braccio_description/meshes/wrist_1.stl" scale="0.001 0.001 0.001" />
            </geometry>
            <material name="liscia_arancione_chiaro" />
        </visual>
        <collision>
            <origin rpy="0 0 0" xyz="-0.325306 0.0002 -1.166901" />
            <geometry>
                <mesh filename="package://braccio_description/meshes/wrist_1.stl" scale="0.001 0.001 0.001" />
            </geometry>
        </collision>
    </link>
    <link name="palm_1">
        <inertial>
            <origin rpy="0 0 0" xyz="-0.00010488173102107812 -3.620761348670275e-08 0.018527069552811692" />
            <mass value="0.03179176708359849" />
            <inertia ixx="7e-06" ixy="-0.0" ixz="-0.0" iyy="7e-06" iyz="-0.0" izz="9e-06" />
        </inertial>
        <visual>
            <origin rpy="0 0 0" xyz="-0.325397 0.0002 -1.150902" />
            <geometry>
                <mesh filename="package://braccio_description/meshes/palm_1.stl" scale="0.001 0.001 0.001" />
            </geometry>
            <material name="liscia_giallo" />
        </visual>
        <collision>
            <origin rpy="0 0 0" xyz="-0.325397 0.0002 -1.150902" />
            <geometry>
                <mesh filename="package://braccio_description/meshes/palm_1.stl" scale="0.001 0.001 0.001" />
            </geometry>
        </collision>
    </link>
    <joint name="Azimuth_joint" type="continuous">
        <origin rpy="0 0 0" xyz="0.325006 0.0 0.419949" />
        <parent link="base_link" />
        <child link="Base_braccio_1" />
        <axis xyz="-0.0 0.0 1.0" />
    </joint>
    <joint name="Elevation_joint" type="continuous">
        <origin rpy="0 0 0" xyz="0.0 0.0 0.0575" />
        <parent link="Base_braccio_1" />
        <child link="link1_1" />
        <axis xyz="-0.0 -1.0 0.0" />
    </joint>
    <joint name="Elbow_joint" type="continuous">
        <origin rpy="0 0 0" xyz="0.0 0.0 0.345" />
        <parent link="link1_1" />
        <child link="Elbow_1" />
        <axis xyz="-0.0 -1.0 0.0" />
    </joint>
    <joint name="joint_3" type="continuous">
        <origin rpy="0 0 0" xyz="0.0 0.0 -0.038" />
        <parent link="Elbow_1" />
        <child link="Link2_1" />
        <axis xyz="-0.0 0.0 1.0" />
    </joint>
    <joint name="wrist_pitch_joint" type="continuous">
        <origin rpy="0 0 0" xyz="0.0003 -0.0002 0.382452" />
        <parent link="Link2_1" />
        <child link="wrist_1" />
        <axis xyz="0.0 1.0 -0.0" />
    </joint>
    <joint name="wrist_roll_joint" type="continuous">
        <origin rpy="0 0 0" xyz="9.1e-05 0.0 -0.015999" />
        <parent link="wrist_1" />
        <child link="palm_1" />
        <axis xyz="-0.005651 -0.0 0.999984" />
    </joint>
</robot>

