<?xml version="1.0" ?>
<robot name="braccio_urdf" xmlns:xacro="http://www.ros.org/wiki/xacro">

<xacro:include filename="$(find braccio_urdf_description)/urdf/materials.xacro" />
<xacro:include filename="$(find braccio_urdf_description)/urdf/braccio_urdf.trans" />
<xacro:include filename="$(find braccio_urdf_description)/urdf/braccio_urdf.gazebo" />

# Fixed joint added later
<link name="world"/>

<joint name="fixed" type="fixed">
	<parent link="world"/>
	<child link="base_link"/>
</joint>

<link name="base_link">
  <inertial>
    <origin rpy="0 0 0" xyz="-2.2915708308599866e-14 1.8798776299097513e-17 0.0025"/>
    <mass value="0.6531371126813174"/>
    <inertia ixx="0.002589" ixy="-0.0" ixz="0.0" iyy="0.002589" iyz="0.0" izz="0.005176"/>
  </inertial>
  <visual>
    <origin rpy="0 0 0" xyz="0 0 0"/>
    <geometry>
      <mesh filename="/home/alessio/ROS/rob_arm_ws_old/src/braccio_urdf_description/meshes/base_link.stl" scale="0.001 0.001 0.001"/>
    </geometry>
    <material name="silver"/>
  </visual>
  <collision>
    <origin rpy="0 0 0" xyz="0 0 0"/>
    <geometry>
      <mesh filename="/home/alessio/ROS/rob_arm_ws_old/src/braccio_urdf_description/meshes/base_link.stl" scale="0.001 0.001 0.001"/>
    </geometry>
  </collision>
</link>

<link name="link1solid_1">
  <inertial>
    <origin rpy="0 0 0" xyz="0.20465715663638878 0.03300000000002991 -8.359131107087137e-05"/>
    <mass value="0.7189946765387882"/>
    <inertia ixx="0.000914" ixy="0.0" ixz="2e-06" iyy="0.012319" iyz="-0.0" izz="0.01279"/>
  </inertial>
  <visual>
    <origin rpy="0 0 0" xyz="-0.054684 0.037 -0.05"/>
    <geometry>
      <mesh filename="/home/alessio/ROS/rob_arm_ws_old/src/braccio_urdf_description/meshes/link1solid_1.stl" scale="0.001 0.001 0.001"/>
    </geometry>
    <material name="silver"/>
  </visual>
  <collision>
    <origin rpy="0 0 0" xyz="-0.054684 0.037 -0.05"/>
    <geometry>
      <mesh filename="/home/alessio/ROS/rob_arm_ws_old/src/braccio_urdf_description/meshes/link1solid_1.stl" scale="0.001 0.001 0.001"/>
    </geometry>
  </collision>
</link>

<link name="link2solid_1">
  <inertial>
    <origin rpy="0 0 0" xyz="0.19864190640938 0.028999904955380275 -3.389660095429181e-06"/>
    <mass value="0.9933837273165442"/>
    <inertia ixx="0.000589" ixy="0.0" ixz="0.0" iyy="0.008118" iyz="0.0" izz="0.008401"/>
  </inertial>
  <visual>
    <origin rpy="0 0 0" xyz="-0.455582 0.034 -0.049906"/>
    <geometry>
      <mesh filename="/home/alessio/ROS/rob_arm_ws_old/src/braccio_urdf_description/meshes/link2solid_1.stl" scale="0.001 0.001 0.001"/>
    </geometry>
    <material name="silver"/>
  </visual>
  <collision>
    <origin rpy="0 0 0" xyz="-0.455582 0.034 -0.049906"/>
    <geometry>
      <mesh filename="/home/alessio/ROS/rob_arm_ws_old/src/braccio_urdf_description/meshes/link2solid_1.stl" scale="0.001 0.001 0.001"/>
    </geometry>
  </collision>
</link>

<link name="link3_1solid_1">
  <inertial>
    <origin rpy="0 0 0" xyz="0.03201501886267 -3.0215316376269036e-07 5.455391159335521e-05"/>
    <mass value="0.3028766441725063"/>
    <inertia ixx="6.2e-05" ixy="0.0" ixz="0.0" iyy="0.000105" iyz="0.0" izz="6.3e-05"/>
  </inertial>
  <visual>
    <origin rpy="0 0 0" xyz="-0.752582 0.005 -0.049906"/>
    <geometry>
      <mesh filename="/home/alessio/ROS/rob_arm_ws_old/src/braccio_urdf_description/meshes/link3_1solid_1.stl" scale="0.001 0.001 0.001"/>
    </geometry>
    <material name="silver"/>
  </visual>
  <collision>
    <origin rpy="0 0 0" xyz="-0.752582 0.005 -0.049906"/>
    <geometry>
      <mesh filename="/home/alessio/ROS/rob_arm_ws_old/src/braccio_urdf_description/meshes/link3_1solid_1.stl" scale="0.001 0.001 0.001"/>
    </geometry>
  </collision>
</link>

<link name="link3_2solid_1">
  <inertial>
    <origin rpy="0 0 0" xyz="0.03332507883303437 -3.708628945831016e-06 -0.02610013245751948"/>
    <mass value="0.3081160915154405"/>
    <inertia ixx="8.1e-05" ixy="-0.0" ixz="0.0" iyy="8.8e-05" iyz="-0.0" izz="6.2e-05"/>
  </inertial>
  <visual>
    <origin rpy="0 0 0" xyz="-0.797473 0.005 -0.074956"/>
    <geometry>
      <mesh filename="/home/alessio/ROS/rob_arm_ws_old/src/braccio_urdf_description/meshes/link3_2solid_1.stl" scale="0.001 0.001 0.001"/>
    </geometry>
    <material name="silver"/>
  </visual>
  <collision>
    <origin rpy="0 0 0" xyz="-0.797473 0.005 -0.074956"/>
    <geometry>
      <mesh filename="/home/alessio/ROS/rob_arm_ws_old/src/braccio_urdf_description/meshes/link3_2solid_1.stl" scale="0.001 0.001 0.001"/>
    </geometry>
  </collision>
</link>

<link name="end_effector_solid_1">
  <inertial>
    <origin rpy="0 0 0" xyz="0.0472043578372191 0.00011595455070262557 -0.005812264911847886"/>
    <mass value="0.19396428128165413"/>
    <inertia ixx="5.1e-05" ixy="1e-06" ixz="-2.6e-05" iyy="0.000229" iyz="1e-06" izz="0.000235"/>
  </inertial>
  <visual>
    <origin rpy="0 0 0" xyz="-0.855473 0.005 -0.048856"/>
    <geometry>
      <mesh filename="/home/alessio/ROS/rob_arm_ws_old/src/braccio_urdf_description/meshes/end_effector_solid_1.stl" scale="0.001 0.001 0.001"/>
    </geometry>
    <material name="silver"/>
  </visual>
  <collision>
    <origin rpy="0 0 0" xyz="-0.855473 0.005 -0.048856"/>
    <geometry>
      <mesh filename="/home/alessio/ROS/rob_arm_ws_old/src/braccio_urdf_description/meshes/end_effector_solid_1.stl" scale="0.001 0.001 0.001"/>
    </geometry>
  </collision>
</link>

<link name="base_assembly_solid_1">
  <inertial>
    <origin rpy="0 0 0" xyz="-0.027123607855717324 -0.012631349184430415 0.026003606781318665"/>
    <mass value="4.600891495085032"/>
    <inertia ixx="0.009952" ixy="-0.001334" ixz="0.001088" iyy="0.011385" iyz="0.000652" izz="0.017425"/>
  </inertial>
  <visual>
    <origin rpy="0 0 0" xyz="-0.0 -0.0 -0.005"/>
    <geometry>
      <mesh filename="/home/alessio/ROS/rob_arm_ws_old/src/braccio_urdf_description/meshes/base_assembly_solid_1.stl" scale="0.001 0.001 0.001"/>
    </geometry>
    <material name="silver"/>
  </visual>
  <collision>
    <origin rpy="0 0 0" xyz="-0.0 -0.0 -0.005"/>
    <geometry>
      <mesh filename="/home/alessio/ROS/rob_arm_ws_old/src/braccio_urdf_description/meshes/base_assembly_solid_1.stl" scale="0.001 0.001 0.001"/>
    </geometry>
  </collision>
</link>

<joint name="giunto1" type="continuous">
  <origin rpy="0 0 0" xyz="0.054684 -0.037 0.045"/>
  <parent link="base_assembly_solid_1"/>
  <child link="link1solid_1"/>
  <axis xyz="-0.0 -1.0 -0.0"/>
</joint>

<joint name="giunto2" type="continuous">
  <origin rpy="0 0 0" xyz="0.400898 0.003 -9.4e-05"/>
  <parent link="link1solid_1"/>
  <child link="link2solid_1"/>
  <axis xyz="-0.0 1.0 0.0"/>
</joint>

<joint name="giunto3" type="continuous">
  <origin rpy="0 0 0" xyz="0.297 0.029 0.0"/>
  <parent link="link2solid_1"/>
  <child link="link3_1solid_1"/>
  <axis xyz="-1.0 -0.0 0.0"/>
</joint>

<joint name="giunto4" type="continuous">
  <origin rpy="0 0 0" xyz="0.044891 0.0 0.02505"/>
  <parent link="link3_1solid_1"/>
  <child link="link3_2solid_1"/>
  <axis xyz="0.0 0.0 1.0"/>
</joint>

<joint name="giunto5" type="continuous">
  <origin rpy="0 0 0" xyz="0.058 0.0 -0.0261"/>
  <parent link="link3_2solid_1"/>
  <child link="end_effector_solid_1"/>
  <axis xyz="1.0 0.0 0.0"/>
</joint>

<joint name="giunto0" type="continuous">
  <origin rpy="0 0 0" xyz="0.0 0.0 0.005"/>
  <parent link="base_link"/>
  <child link="base_assembly_solid_1"/>
  <axis xyz="0.0 0.0 -1.0"/>
</joint>

</robot>
