<?xml version="1.0" ?>
<robot name="braccio3_urdf" xmlns:xacro="http://www.ros.org/wiki/xacro">

<xacro:include filename="$(find braccio3_urdf_description)/urdf/materials.xacro" />
<xacro:include filename="$(find braccio3_urdf_description)/urdf/braccio3_urdf.trans" />
<xacro:include filename="$(find braccio3_urdf_description)/urdf/braccio3_urdf.gazebo" />

# Fixed joint added later
<link name="world"/>

<joint name="fixed" type="fixed">
	<parent link="world"/>
	<child link="base_link"/>
</joint>

<!-- Each time there is a mesh tag, I edited the filename attribute, putting the absolute path in my pc instead of package://-->
<!-- As an example: <mesh filename="package://braccio3_urdf_description/meshes/base_link.stl" -->
<!-- becomes <mesh filename="/home/alessio/ROS/Robotic-Arm/rob_arm_ws/src/braccio3_urdf_description/meshes/base_link.stl" -->
<link name="base_link">
  <inertial>
    <origin xyz="0.004168647512765638 0.20951745229773763 0.1935375497398076" rpy="0 0 0"/>
    <mass value="836.9434806625367"/>
    <inertia ixx="25.378744" iyy="45.609186" izz="46.318922" ixy="-0.05972" iyz="-0.03492" ixz="-1.535794"/>
  </inertial>
  <visual>
    <origin xyz="0 0 0" rpy="0 0 0"/>
    <geometry>
      <mesh filename="/home/alessio/ROS/Robotic-Arm/rob_arm_ws/src/braccio3_urdf_description/meshes/base_link.stl" scale="0.001 0.001 0.001"/>
    </geometry>
    <material name="silver"/>
  </visual>
  <collision>
    <origin xyz="0 0 0" rpy="0 0 0"/>
    <geometry>
      <mesh filename="/home/alessio/ROS/Robotic-Arm/rob_arm_ws/src/braccio3_urdf_description/meshes/base_link.stl" scale="0.001 0.001 0.001"/>
    </geometry>
  </collision>
</link>

<link name="link3_1">
  <inertial>
    <origin xyz="-0.040508066073370874 0.0008125047247498074 -4.7615962406322154e-07" rpy="0 0 0"/>
    <mass value="0.5514308868817546"/>
    <inertia ixx="0.000226" iyy="0.000336" izz="0.00046" ixy="1e-06" iyz="-0.0" ixz="-0.0"/>
  </inertial>
  <visual>
    <origin xyz="0.769096 -0.210118 -0.546377" rpy="0 0 0"/>
    <geometry>
      <mesh filename="/home/alessio/ROS/Robotic-Arm/rob_arm_ws/src/braccio3_urdf_description/meshes/link3_1.stl" scale="0.001 0.001 0.001"/>
    </geometry>
    <material name="silver"/>
  </visual>
  <collision>
    <origin xyz="0.769096 -0.210118 -0.546377" rpy="0 0 0"/>
    <geometry>
      <mesh filename="/home/alessio/ROS/Robotic-Arm/rob_arm_ws/src/braccio3_urdf_description/meshes/link3_1.stl" scale="0.001 0.001 0.001"/>
    </geometry>
  </collision>
</link>

<link name="link3_2_1">
  <inertial>
    <origin xyz="-0.03338065953759317 0.03125070642561517 -5.733290932674606e-06" rpy="0 0 0"/>
    <mass value="0.33834836463148793"/>
    <inertia ixx="0.000122" iyy="8.2e-05" izz="0.000139" ixy="-0.0" iyz="0.0" ixz="0.0"/>
  </inertial>
  <visual>
    <origin xyz="0.831096 -0.178618 -0.546377" rpy="0 0 0"/>
    <geometry>
      <mesh filename="/home/alessio/ROS/Robotic-Arm/rob_arm_ws/src/braccio3_urdf_description/meshes/link3_2_1.stl" scale="0.001 0.001 0.001"/>
    </geometry>
    <material name="silver"/>
  </visual>
  <collision>
    <origin xyz="0.831096 -0.178618 -0.546377" rpy="0 0 0"/>
    <geometry>
      <mesh filename="/home/alessio/ROS/Robotic-Arm/rob_arm_ws/src/braccio3_urdf_description/meshes/link3_2_1.stl" scale="0.001 0.001 0.001"/>
    </geometry>
  </collision>
</link>

<link name="Endeffector_1">
  <inertial>
    <origin xyz="-0.06284753310822067 -0.0006242490393161271 -0.001735499854313538" rpy="0 0 0"/>
    <mass value="0.560678619435505"/>
    <inertia ixx="0.00018" iyy="0.000754" izz="0.0008" ixy="4e-06" iyz="-5e-06" ixz="1.2e-05"/>
  </inertial>
  <visual>
    <origin xyz="0.889572 -0.209868 -0.546377" rpy="0 0 0"/>
    <geometry>
      <mesh filename="/home/alessio/ROS/Robotic-Arm/rob_arm_ws/src/braccio3_urdf_description/meshes/Endeffector_1.stl" scale="0.001 0.001 0.001"/>
    </geometry>
    <material name="silver"/>
  </visual>
  <collision>
    <origin xyz="0.889572 -0.209868 -0.546377" rpy="0 0 0"/>
    <geometry>
      <mesh filename="/home/alessio/ROS/Robotic-Arm/rob_arm_ws/src/braccio3_urdf_description/meshes/Endeffector_1.stl" scale="0.001 0.001 0.001"/>
    </geometry>
  </collision>
</link>

<link name="base_1">
  <inertial>
    <origin xyz="0.025393314451362864 0.009090552866910295 0.024636070488622874" rpy="0 0 0"/>
    <mass value="3.64909788737888"/>
    <inertia ixx="0.006153" iyy="0.006117" izz="0.009664" ixy="-0.000566" iyz="-0.000236" ixz="-0.000765"/>
  </inertial>
  <visual>
    <origin xyz="0.160556 -0.209318 -0.48923" rpy="0 0 0"/>
    <geometry>
      <mesh filename="/home/alessio/ROS/Robotic-Arm/rob_arm_ws/src/braccio3_urdf_description/meshes/base_1.stl" scale="0.001 0.001 0.001"/>
    </geometry>
    <material name="silver"/>
  </visual>
  <collision>
    <origin xyz="0.160556 -0.209318 -0.48923" rpy="0 0 0"/>
    <geometry>
      <mesh filename="/home/alessio/ROS/Robotic-Arm/rob_arm_ws/src/braccio3_urdf_description/meshes/base_1.stl" scale="0.001 0.001 0.001"/>
    </geometry>
  </collision>
</link>

<link name="link1_1">
  <inertial>
    <origin xyz="-0.16451719857997738 -0.0430447639546126 0.0011081259360844475" rpy="0 0 0"/>
    <mass value="2.4895771261642063"/>
    <inertia ixx="0.001986" iyy="0.021056" izz="0.021749" ixy="0.001167" iyz="-8e-06" ixz="-0.000146"/>
  </inertial>
  <visual>
    <origin xyz="0.180556 -0.249818 -0.542706" rpy="0 0 0"/>
    <geometry>
      <mesh filename="/home/alessio/ROS/Robotic-Arm/rob_arm_ws/src/braccio3_urdf_description/meshes/link1_1.stl" scale="0.001 0.001 0.001"/>
    </geometry>
    <material name="silver"/>
  </visual>
  <collision>
    <origin xyz="0.180556 -0.249818 -0.542706" rpy="0 0 0"/>
    <geometry>
      <mesh filename="/home/alessio/ROS/Robotic-Arm/rob_arm_ws/src/braccio3_urdf_description/meshes/link1_1.stl" scale="0.001 0.001 0.001"/>
    </geometry>
  </collision>
</link>

<link name="link2_1">
  <inertial>
    <origin xyz="-0.17400134010695056 0.03513435089959677 0.0031921811892481333" rpy="0 0 0"/>
    <mass value="1.7070688721165612"/>
    <inertia ixx="0.001103" iyy="0.015999" izz="0.015998" ixy="-4e-05" iyz="1e-06" ixz="-3.6e-05"/>
  </inertial>
  <visual>
    <origin xyz="0.475556 -0.175118 -0.542706" rpy="0 0 0"/>
    <geometry>
      <mesh filename="/home/alessio/ROS/Robotic-Arm/rob_arm_ws/src/braccio3_urdf_description/meshes/link2_1.stl" scale="0.001 0.001 0.001"/>
    </geometry>
    <material name="silver"/>
  </visual>
  <collision>
    <origin xyz="0.475556 -0.175118 -0.542706" rpy="0 0 0"/>
    <geometry>
      <mesh filename="/home/alessio/ROS/Robotic-Arm/rob_arm_ws/src/braccio3_urdf_description/meshes/link2_1.stl" scale="0.001 0.001 0.001"/>
    </geometry>
  </collision>
</link>

<joint name="Giunto3" type="continuous">
  <origin xyz="-0.29354 0.035 0.003671" rpy="0 0 0"/>
  <parent link="link2_1"/>
  <child link="link3_1"/>
  <axis xyz="-1.0 -0.0 0.0"/>
</joint>

<joint name="Giunto4" type="continuous">
  <origin xyz="-0.062 -0.0315 0.0" rpy="0 0 0"/>
  <parent link="link3_1"/>
  <child link="link3_2_1"/>
  <axis xyz="-0.0 1.0 0.0"/>
</joint>

<joint name="Giunto5" type="continuous">
  <origin xyz="-0.058476 0.03125 0.0" rpy="0 0 0"/>
  <parent link="link3_2_1"/>
  <child link="Endeffector_1"/>
  <axis xyz="-1.0 0.0 0.0"/>
</joint>

<joint name="Giunto0" type="continuous">
  <origin xyz="-0.160556 0.209318 0.48923" rpy="0 0 0"/>
  <parent link="base_link"/>
  <child link="base_1"/>
  <axis xyz="-0.0 -0.0 1.0"/>
</joint>

<joint name="Giunto1" type="continuous">
  <origin xyz="-0.02 0.0405 0.053476" rpy="0 0 0"/>
  <parent link="base_1"/>
  <child link="link1_1"/>
  <axis xyz="0.0 1.0 0.0"/>
</joint>

<joint name="Giunto2" type="continuous">
  <origin xyz="-0.295 -0.0747 0.0" rpy="0 0 0"/>
  <parent link="link1_1"/>
  <child link="link2_1"/>
  <axis xyz="0.0 -1.0 -0.0"/>
</joint>

</robot>
